Workbook
Name DB: #REF!
Name KIM: 'INSERITO KIM'!$1:$1048576
Name RES: COMSY!$E$5:$E$58
Name SHP: COMSY!#REF!

Sheet PIVOT
A1: AM | B1: (Tutto)
A2: Data Inserimento Ordine | B2: (Tutto)
D3: Etichette di riga | E3: INSERITO | G3: Etichette di riga | H3: INSERITO | J3: Etichette di riga | K3: Count of Valore
A4: Etichette di riga | B4: INSERITO | D4: Giacomo | E4: 167 | G4: Fastweb NeXXt Mobile | H4: 137 | J4: FISSO | K4: 86
A5: S.I.P.R.A. ITALIA SAS DI LASALVIA M. & MONTERISI G. | B5: 22 | D5: FISSO | E5: 53 | G5: Fastweb Casa light | H5: 66 | J5: MOBILE | K5: 159
A6: FISSO | B6: 11 | D6: MOBILE | E6: 114 | G6: Fastweb NeXXt One Casa | H6: 17 | J6: Totale complessivo | K6: 245
A7: MOBILE | B7: 11 | D7: Luigi | E7: 40 | G7: Fastweb Mobile | H7: 11
A8: INFOPOINT DI DEL VECCHIO ROSA E CORTIGIANO CARMELA | B8: 19 | D8: FISSO | E8: 19 | G8: Fastweb Mobile Unlimited | H8: 4
A9: FISSO | B9: 5 | D9: MOBILE | E9: 21 | G9: Fastweb NeXXt Mobile Mini | H9: 4
A10: MOBILE | B10: 14 | D10: Raffaele | E10: 29 | G10: Fastweb NeXXt Mobile Business | H10: 3 | J10: Etichette di riga | K10: Count of Valore
A11: MEDIA CENTER DI LUCA BARBERIO | B11: 15 | D11: FISSO | E11: 11 | G11: Fastweb NeXXt One Business | H11: 1 | J11: FISSO | K11: 86
A12: FISSO | B12: 5 | D12: MOBILE | E12: 18 | G12: Fastweb Business Light | H12: 1 | J12: RES | K12: 84
A13: MOBILE | B13: 10 | D13: Armando | E13: 6 | G13: Fastweb NeXXt One Casa FWA | H13: 1 | J13: SHP | K13: 2
A14: MILILLO GIUSEPPE | B14: 14 | D14: FISSO | E14: 3 | G14: Totale complessivo | H14: 245 | J14: MOBILE | K14: 159
A15: FISSO | B15: 8 | D15: MOBILE | E15: 3 | J15: RES | K15: 156
A16: MOBILE | B16: 6 | D16: KIM | E16: 3 | J16: SHP | K16: 3
A17: BOXSTORE DI SAVINO | B17: 12 | D17: MOBILE | E17: 3 | J17: Totale complessivo | K17: 245
A18: FISSO | B18: 4 | D18: Totale complessivo | E18: 245
A19: MOBILE | B19: 8
A20: RISOLTO LAB MONOPOLI | B20: 12
A21: FISSO | B21: 6
A22: MOBILE | B22: 6
A23: HUB 98 di DRAGONE GIUSEPPE | B23: 11
A24: FISSO | B24: 3
A25: MOBILE | B25: 8
A26: DECOM | B26: 9
A27: FISSO | B27: 3
A28: MOBILE | B28: 6
A29: NICK TEL DI NICOLA MASTROCRISTINO | B29: 9
A30: MOBILE | B30: 9
... A154: Totale complessivo | B154: 245

Sheet INCASSI
A3: Etichette di riga | B3: Count of Valore | C3: Sum of VASC
A4: BECLARI ELECTRONICS | B4: 1 | C4: 20
A5: Fastweb NeXXt Mobile | B5: 1 | C5: 20
A6: CARTOPLANET DI GIUSEPPE RUBINI | B6: 1 | C6: 20
A7: Fastweb NeXXt Mobile | B7: 1 | C7: 20
A8: CASALUCI S.R.L. | B8: 1 | C8: 20
A9: Fastweb NeXXt Mobile | B9: 1 | C9: 20
A10: CELLULAR PARK DI MAGGIO ANTONIO | B10: 1 | C10: 20
A11: Fastweb NeXXt Mobile | B11: 1 | C11: 20
A12: DEBATECH DI DE PIANO DINA | B12: 5 | C12: 100
A13: Fastweb Mobile | B13: 1 | C13: 20
A14: Fastweb NeXXt Mobile | B14: 4 | C14: 80
A15: GALLITELLI ANTONIO | B15: 3 | C15: 60
... A153: Totale complessivo | B153: 222 | C153: 3121.2

Sheet COMSY
E5: Codice RES | F5: NOME POINT | G5: AM | H5: MAIL | I5: SEGMENTO | J5: POINT A ZERO
E6: NR.1217.0601NA | F6: KIM | G6: KIM | I6: RES | J6: =+_xlfn.XLOOKUP(E6,#REF!,F:F,"ZERO",0,1) -> #REF!
E7: NR.1217.0601NA.C0001 | F7: APULIATOURIST2.0 | G7: Giacomo | I7: RES | J7: =+_xlfn.XLOOKUP(E7,#REF!,F:F,"ZERO",0,1) -> #REF!
E8: NR.1217.0601NA.C0002 | F8: GIACOMO ROSATO | G8: Armando | I8: RES | J8: =+_xlfn.XLOOKUP(E8,#REF!,F:F,"ZERO",0,1) -> #REF!
E9: NR.1217.0601NA.C0003 | F9: MILILLO GIUSEPPE | G9: Giacomo | I9: RES | J9: =+_xlfn.XLOOKUP(E9,#REF!,F:F,"ZERO",0,1) -> #REF!
E10: NR.1217.0601NA.C0004 | F10: MEDIA CENTER DI LUCA BARBERIO | G10: Giacomo | I10: RES | J10: =+_xlfn.XLOOKUP(E10,#REF!,F:F,"ZERO",0,1) -> #REF!
E11: NR.1217.0601NA.C0005 | F11: BECLARI ELECTRONICS | G11: Giacomo | I11: RES | J11: =+_xlfn.XLOOKUP(E11,#REF!,F:F,"ZERO",0,1) -> #REF!
E12: NR.1217.0601NA.C0006 | F12: REX | G12: Armando | I12: RES | J12: =+_xlfn.XLOOKUP(E12,#REF!,F:F,"ZERO",0,1) -> #REF!
E13: NR.1217.0601NA.C0007 | F13: MONDO TELEFONO DI VITULLI ANGELA | G13: Giacomo | I13: RES | J13: =+_xlfn.XLOOKUP(E13,#REF!,F:F,"ZERO",0,1) -> #REF!
E14: NR.1217.0601NA.C0010 | F14: ELETTROCCASIONE S.A.S. DI DE RUVO VINCENZO | G14: Giacomo | I14: RES | J14: =+_xlfn.XLOOKUP(E14,#REF!,F:F,"ZERO",0,1) -> #REF!
E15: NR.1217.0601NA.C0011 | F15: WIRELESS TECHNOLOGY DI INNANGI DESIDERIA | G15: Luigi | I15: RES | J15: =+_xlfn.XLOOKUP(E15,#REF!,F:F,"ZERO",0,1) -> #REF!
E16: NR.1217.0601NA.C0012 | F16: INFOPOINT DI DEL VECCHIO ROSA E CORTIGIANO CARMELA | G16: Giacomo | I16: RES | J16: =+_xlfn.XLOOKUP(E16,#REF!,F:F,"ZERO",0,1) -> #REF!
E17: NR.1217.0601NA.C0013 | F17: PC CENTER DI LACAVA MASSIMO GIUSEPPE | G17: Armando | I17: RES | J17: =+_xlfn.XLOOKUP(E17,#REF!,F:F,"ZERO",0,1) -> #REF!
E18: NR.1217.0601NA.C0014 | F18: CATANZARO LUIGI | G18: Giacomo | I18: RES | J18: =+_xlfn.XLOOKUP(E18,#REF!,F:F,"ZERO",0,1) -> #REF!
E19: NR.1217.0601NA.C0015 | F19: CARTO-EDICOLA KEPLERO DI CITTO DANIEL | G19: Raffaele | H19: Chiuso | I19: SHP | J19: =+_xlfn.XLOOKUP(E19,#REF!,F:F,"ZERO",0,1) -> #REF!
E20: NR.1217.0601NA.C0016 | F20: HITECH S.R.L.S. | G20: Raffaele | H20: Chiuso | I20: SHP | J20: =+_xlfn.XLOOKUP(E20,#REF!,F:F,"ZERO",0,1) -> #REF!
E21: NR.1217.0601NA.C0017 | F21: CELLULANDIA DI SPAGNOLO IRINELLA | G21: Raffaele | I21: RES | J21: =+_xlfn.XLOOKUP(E21,#REF!,F:F,"ZERO",0,1) -> #REF!
E22: NR.1217.0601NA.C0018 | F22: PRENCIPE MASSIMO | G22: Raffaele | H22: Chiuso | I22: RES | J22: =+_xlfn.XLOOKUP(E22,#REF!,F:F,"ZERO",0,1) -> #REF!
E23: NR.1217.0601NA.C0019 | F23: DE TOMMASO ANTONIO | G23: Giacomo | I23: RES | J23: =+_xlfn.XLOOKUP(E23,#REF!,F:F,"ZERO",0,1) -> #REF!
E24: NR.1217.0601NA.C0020 | F24: CARTOPLANET DI GIUSEPPE RUBINI | G24: Giacomo | I24: RES | J24: =+_xlfn.XLOOKUP(E24,#REF!,F:F,"ZERO",0,1) -> #REF!
E25: NR.1217.0601NA.C0022 | F25: PUNTOCOM DI BONITO MARIALUIGIA | G25: Giacomo | I25: RES | J25: =+_xlfn.XLOOKUP(E25,#REF!,F:F,"ZERO",0,1) -> #REF!
E26: NR.1217.0601NA.C0023 | F26: INFOTECNOLAB DI SCURO TEODORO | G26: Armando | I26: SHP | J26: =+_xlfn.XLOOKUP(E26,#REF!,F:F,"ZERO",0,1) -> #REF!
E27: NR.1217.0601NA.C0024 | F27: EXATEL STORE | G27: Giacomo | I27: RES | J27: =+_xlfn.XLOOKUP(E27,#REF!,F:F,"ZERO",0,1) -> #REF!
E28: NR.1217.0601NA.C0025 | F28: TABACCHERIA MAGALDI DAL 1959 DI GENTILE AMALIA | G28: Raffaele | H28: Chiuso | I28: RES | J28: =+_xlfn.XLOOKUP(E28,#REF!,F:F,"ZERO",0,1) -> #REF!
E29: NR.1217.0601NA.C0026 | F29: BAR DOC DI IAMMARINO ALESSANDRO | G29: Raffaele | I29: SHP | J29: =+_xlfn.XLOOKUP(E29,#REF!,F:F,"ZERO",0,1) -> #REF!
E30: NR.1217.0601NA.C0027 | F30: A.G. TECHNOLOGY TRADE di ANDREA GARGANO | G30: Giacomo | I30: RES | J30: =+_xlfn.XLOOKUP(E30,#REF!,F:F,"ZERO",0,1) -> #REF!
E31: NR.1217.0601NA.C0029 | F31: ONLINE 5 SRLS | G31: Armando | I31: RES | J31: =+_xlfn.XLOOKUP(E31,#REF!,F:F,"ZERO",0,1) -> #REF!
E32: NR.1217.0601NA.C0030 | F32: WHITE CITY REPAIR di PINTO ROSSANA | G32: Raffaele | I32: RES | J32: =+_xlfn.XLOOKUP(E32,#REF!,F:F,"ZERO",0,1) -> #REF!
E33: NR.1217.0601NA.C0032 | F33: FEDERASSICURAZIONI DI RIZZELLO FEDERICA | G33: Raffaele | H33: Chiuso | I33: RES | J33: =+_xlfn.XLOOKUP(E33,#REF!,F:F,"ZERO",0,1) -> #REF!
E34: NR.1217.0601NA.C0033 | F34: DISCOMANIA MIX DI PACIFICO RINALDO | G34: Raffaele | I34: RES | J34: =+_xlfn.XLOOKUP(E34,#REF!,F:F,"ZERO",0,1) -> #REF!
E35: NR.1217.0601NA.C0034 | F35: PUNTO LED DI DE FILIPPO GIOACCHINO | G35: Raffaele | I35: RES | J35: =+_xlfn.XLOOKUP(E35,#REF!,F:F,"ZERO",0,1) -> #REF!
E36: NR.1217.0601NA.C0035 | F36: CELLULAR PARK DI MAGGIO ANTONIO | G36: Giacomo | I36: SHP | J36: =+_xlfn.XLOOKUP(E36,#REF!,F:F,"ZERO",0,1) -> #REF!
E37: NR.1217.0601NA.C0036 | F37: COMPUTER WORLD DI SANTORSA GIUSEPPE | G37: Raffaele | H37: Chiuso | I37: RES | J37: =+_xlfn.XLOOKUP(E37,#REF!,F:F,"ZERO",0,1) -> #REF!
E38: NR.1217.0601NA.C0039 | F38: NORBATEL DI PASCALE ALESSANDRO | G38: Giacomo | I38: RES | J38: =+_xlfn.XLOOKUP(E38,#REF!,F:F,"ZERO",0,1) -> #REF!
E39: NR.1217.0601NA.C0040 | F39: ITEL STORE DI LANZOLLA GIOVANNI | G39: Giacomo | I39: RES | J39: =+_xlfn.XLOOKUP(E39,#REF!,F:F,"ZERO",0,1) -> #REF!
E40: NR.1217.0601NA.C0041 | F40: LEVAPHONE DI LEVA ANTONIO | G40: Giacomo | I40: RES | J40: =+_xlfn.XLOOKUP(E40,#REF!,F:F,"ZERO",0,1) -> #REF!
E41: NR.1217.0601NA.C0042 | F41: DODICI RE SRLS | G41: Raffaele | I41: RES | J41: =+_xlfn.XLOOKUP(E41,#REF!,F:F,"ZERO",0,1) -> #REF!
E42: NR.1217.0601NA.C0043 | F42: FOTO ALL TECHNOLOGIES DI FUINA COSIMO DAMIANO | G42: Giacomo | I42: SHP | J42: =+_xlfn.XLOOKUP(E42,#REF!,F:F,"ZERO",0,1) -> #REF!
E43: NR.1217.0601NA.C0044 | F43: MEGAPHONE DI PELLEGRINO GIUSEPPINA | G43: Raffaele | H43: Chiuso | I43: RES | J43: =+_xlfn.XLOOKUP(E43,#REF!,F:F,"ZERO",0,1) -> #REF!
E44: NR.1217.0601NA.C0045 | F44: MASS TECH S.R.L.S. | G44: Giacomo | I44: RES | J44: =+_xlfn.XLOOKUP(E44,#REF!,F:F,"ZERO",0,1) -> #REF!
...

Sheet PIANI
A1: VALORE | B1: TIPO | C1: SEGMENTO | D1: INCASSO
A2: Fastweb Casa light | B2: FISSO | C2: RES
A3: Fastweb Mobile | B3: MOBILE | C3: RES | D3: 20 | F3: 9.95
A4: Fastweb Mobile Voce | B4: MOBILE | C4: RES | D4: 20 | F4: 5.95
A5: Fastweb NeXXt Business Light | B5: FISSO | C5: SHP
A6: Fastweb NeXXt Casa light | B6: FISSO | C6: RES
A7: Fastweb NeXXt Mobile | B7: MOBILE | C7: RES | D7: 20 | F7: 7.95
A8: Fastweb NeXXt Mobile Business | B8: MOBILE | C8: SHP | D8: 24.4
A9: Fastweb NeXXt Mobile Mini | B9: MOBILE | C9: RES | D9: 22 | F9: 11.95
A10: FastwebCasa NeXXt casa | B10: FISSO | C10: RES
A11: Mobile a Consumo | B11: MOBILE | C11: RES | D11: 21
A12: Fastweb Business Light | B12: FISSO | C12: SHP
A13: Fastweb NeXXt Casa | B13: FISSO | C13: RES
A14: Fastweb Mobile Ver3 | B14: MOBILE | C14: RES | D14: 20
A15: Fastweb Mobile Dati | B15: MOBILE | C15: RES | D15: 30
A16: Fastweb Mobile Light | B16: MOBILE | C16: RES | D16: 20
A17: Fastweb NeXXt Business | B17: FISSO | C17: SHP
A18: Fastweb Casa FWA | B18: FISSO | C18: RES
A19: Fastweb Casa Light FWA | B19: FISSO | C19: RES
A20: Fastweb Mobile Voce (Light) | B20: MOBILE | C20: RES | D20: 20
A21: Fastweb Mobile Light Ver2 | B21: MOBILE | C21: RES | D21: 20
A22: Fastweb Mobile Ver2 | B22: MOBILE | C22: RES | D22: 20
A23: Fastweb NeXXt Mobile Business Freedom | B23: MOBILE | C23: SHP | D23: 24.4
A24: Fastweb Mobile NeXXt Backup | B24: MOBILE | C24: SHP | D24: 0
A25: Fastweb NeXXt One Casa | B25: FISSO | C25: RES
A26: Fastweb NeXXt One Business | B26: FISSO | C26: SHP
A27: Mobile Business | B27: MOBILE | C27: SHP
A28: Fastweb NeXXt Mobile Business Unlimited | B28: MOBILE | C28: SHP
A29: Fastweb Mobile Unlimited | B29: MOBILE | C29: RES
A30: Fastweb NeXXt One Casa FWA | B30: FISSO | C30: RES

Sheet INSERITO KIM
A1: Cliente | B1: FiscalCodeOrPiva | C1: Segmento | D1: AccountNumber | E1: Codice Ordine | F1: Codice Comsy Tecnico Attuale | G1: Contributo | H1: Tipo Ordine | I1: Canone | J1: Stato dell'ordine CPQ | K1: Stato dell'Ordine OM | L1: Data Inserimento Ordine | M1: Valore | N1: POINT | O1: AM | P1: TIPO | Q1: VASC
A2: PINEAPPLE | B2: 09064000723 | C2: SHP | D2: 24340523 | E2: OR-0030650638 | F2: NS.1638.0601NA.C0012 | G2: 329 | H2: FISSO | I2: 23.95 | J2: Inviato | K2: Attesa provisioning | L2: 45909 | M2: Fastweb Business Light | N2: =+INDEX(COMSY!F:F,MATCH(INSERITO_KIM[[#This Row],[Codice Comsy Tecnico Attuale]],COMSY!E:E,0)) -> INFOPOINT DI DEL VECCHIO ROSA E CORTIGIANO CARMELA | O2: =+INDEX(COMSY!G:G,MATCH(INSERITO_KIM[[#This Row],[Codice Comsy Tecnico Attuale]],COMSY!E:E,0)) -> Giacomo | P2: =+INDEX(PIANI!B:B,MATCH(INSERITO_KIM[[#This Row],[Valore]],PIANI!A:A,0)) -> FISSO | Q2: =+INDEX(PIANI!D:D,MATCH(INSERITO_KIM[[#This Row],[Valore]],PIANI!A:A,0)) -> 0
A3: GIOVANNA TATONE | B3: TTNGNN83C41A662T | C3: RES | D3: 24375407 | E3: OR-0030623342 | F3: NR.1217.0601NA.C0003 | G3: 20 | H3: FISSO E MOBILE | I3: 33.9 | J3: Inviato | K3: Attesa provisioning | L3: 45906 | M3: Fastweb Casa light | N3: =+INDEX(COMSY!F:F,MATCH(INSERITO_KIM[[#This Row],[Codice Comsy Tecnico Attuale]],COMSY!E:E,0)) -> MILILLO GIUSEPPE | O3: =+INDEX(COMSY!G:G,MATCH(INSERITO_KIM[[#This Row],[Codice Comsy Tecnico Attuale]],COMSY!E:E,0)) -> Giacomo | P3: =+INDEX(PIANI!B:B,MATCH(INSERITO_KIM[[#This Row],[Valore]],PIANI!A:A,0)) -> FISSO | Q3: =+INDEX(PIANI!D:D,MATCH(INSERITO_KIM[[#This Row],[Valore]],PIANI!A:A,0)) -> 0
A4: MARIA SANTA MARIANI | B4: MRNMSN68L56C436M | C4: RES | D4: 24379721 | E4: OR-0030640016 | F4: NR.1217.0601NA.C0003 | G4: 0 | H4: FISSO | I4: 27.95 | J4: Inviato | K4: Attesa provisioning | L4: 45908 | M4: Fastweb Casa light | N4: =+INDEX(COMSY!F:F,MATCH(INSERITO_KIM[[#This Row],[Codice Comsy Tecnico Attuale]],COMSY!E:E,0)) -> MILILLO GIUSEPPE | O4: =+INDEX(COMSY!G:G,MATCH(INSERITO_KIM[[#This Row],[Codice Comsy Tecnico Attuale]],COMSY!E:E,0)) -> Giacomo | P4: =+INDEX(PIANI!B:B,MATCH(INSERITO_KIM[[#This Row],[Valore]],PIANI!A:A,0)) -> FISSO | Q4: =+INDEX(PIANI!D:D,MATCH(INSERITO_KIM[[#This Row],[Valore]],PIANI!A:A,0)) -> 0
A5: FRANCESCO MASSARO | B5: MSSFNC80M16A048W | C5: RES | D5: 24384367 | E5: OR-0030659976 | F5: NR.1217.0601NA.C0004 | G5: 40 | H5: FISSO E MOBILE | I5: 43.85 | J5: Inviato | K5: Attesa provisioning | L5: 45910 | M5: Fastweb Casa light | N5: =+INDEX(COMSY!F:F,MATCH(INSERITO_KIM[[#This Row],[Codice Comsy Tecnico Attuale]],COMSY!E:E,0)) -> MEDIA CENTER DI LUCA BARBERIO | O5: =+INDEX(COMSY!G:G,MATCH(INSERITO_KIM[[#This Row],[Codice Comsy Tecnico Attuale]],COMSY!E:E,0)) -> Giacomo | P5: =+INDEX(PIANI!B:B,MATCH(INSERITO_KIM[[#This Row],[Valore]],PIANI!A:A,0)) -> FISSO | Q5: =+INDEX(PIANI!D:D,MATCH(INSERITO_KIM[[#This Row],[Valore]],PIANI!A:A,0)) -> 0
A6: MARIAGRAZIA PARADISO | B6: PRDMGR88C58E038Y | C6: RES | D6: 20030402 | E6: OR-0030682786 | F6: NR.1217.0601NA.C0004 | G6: 0 | H6: FISSO | I6: 23.95 | J6: Inviato | K6: Attesa provisioning | L6: 45912 | M6: Fastweb Casa light | N6: =+INDEX(COMSY!F:F,MATCH(INSERITO_KIM[[#This Row],[Codice Comsy Tecnico Attuale]],COMSY!E:E,0)) -> MEDIA CENTER DI LUCA BARBERIO | O6: =+INDEX(COMSY!G:G,MATCH(INSERITO_KIM[[#This Row],[Codice Comsy Tecnico Attuale]],COMSY!E:E,0)) -> Giacomo | P6: =+INDEX(PIANI!B:B,MATCH(INSERITO_KIM[[#This Row],[Valore]],PIANI!A:A,0)) -> FISSO | Q6: =+INDEX(PIANI!D:D,MATCH(INSERITO_KIM[[#This Row],[Valore]],PIANI!A:A,0)) -> 0
A7: LUCIA BINO | B7: BNILCU90A57L049T | C7: RES | D7: 24379923 | E7: OR-0030640456 | F7: NR.1217.0601NA.C0013 | G7: 0 | H7: FISSO | I7: 27.95 | J7: Inviato | K7: Attesa provisioning | L7: 45908 | M7: Fastweb Casa light | N7: =+INDEX(COMSY!F:F,MATCH(INSERITO_KIM[[#This Row],[Codice Comsy Tecnico Attuale]],COMSY!E:E,0)) -> PC CENTER DI LACAVA MASSIMO GIUSEPPE | O7: =+INDEX(COMSY!G:G,MATCH(INSERITO_KIM[[#This Row],[Codice Comsy Tecnico Attuale]],COMSY!E:E,0)) -> Armando | P7: =+INDEX(PIANI!B:B,MATCH(INSERITO_KIM[[#This Row],[Valore]],PIANI!A:A,0)) -> FISSO | Q7: =+INDEX(PIANI!D:D,MATCH(INSERITO_KIM[[#This Row],[Valore]],PIANI!A:A,0)) -> 0
A8: MICHELE PASTORE | B8: PSTMHL99H02F027W | C8: RES | D8: 24365675 | E8: OR-0030581685 | F8: NR.1217.0601NA.C0127 | G8: 0 | H8: FISSO | I8: 27.95 | J8: Inviato | K8: Attesa provisioning | L8: 45902 | M8: Fastweb Casa light | N8: =+INDEX(COMSY!F:F,MATCH(INSERITO_KIM[[#This Row],[Codice Comsy Tecnico Attuale]],COMSY!E:E,0)) -> HDC REPAIR SERVICE DI FRANCAVILLA MICHELE | O8: =+INDEX(COMSY!G:G,MATCH(INSERITO_KIM[[#This Row],[Codice Comsy Tecnico Attuale]],COMSY!E:E,0)) -> Giacomo | P8: =+INDEX(PIANI!B:B,MATCH(INSERITO_KIM[[#This Row],[Valore]],PIANI!A:A,0)) -> FISSO | Q8: =+INDEX(PIANI!D:D,MATCH(INSERITO_KIM[[#This Row],[Valore]],PIANI!A:A,0)) -> 0
A9: MICHELE RICCIARDI | B9: RCCMHL59E14E946K | C9: RES | D9: 24372278 | E9: OR-0030610673 | F9: NR.1217.0601NA.C0159 | G9: 20 | H9: FISSO E MOBILE | I9: 33.9 | J9: Inviato | K9: In Lavorazione | L9: 45904 | M9: Fastweb Casa light | N9: =+INDEX(COMSY!F:F,MATCH(INSERITO_KIM[[#This Row],[Codice Comsy Tecnico Attuale]],COMSY!E:E,0)) -> BOXSTORE DI SAVINO | O9: =+INDEX(COMSY!G:G,MATCH(INSERITO_KIM[[#This Row],[Codice Comsy Tecnico Attuale]],COMSY!E:E,0)) -> Giacomo | P9: =+INDEX(PIANI!B:B,MATCH(INSERITO_KIM[[#This Row],[Valore]],PIANI!A:A,0)) -> FISSO | Q9: =+INDEX(PIANI!D:D,MATCH(INSERITO_KIM[[#This Row],[Valore]],PIANI!A:A,0)) -> 0
A10: DONATELLA DELL'ANNA | B10: DLLDTL93C64E506W | C10: RES | D10: 24390378 | E10: OR-0030679070 | F10: NR.1217.0601NA.C0178 | G10: 20 | H10: FISSO E MOBILE | I10: 33.9 | J10: Inviato | K10: Attesa provisioning | L10: 45911 | M10: Fastweb Casa light | N10: =+INDEX(COMSY!F:F,MATCH(INSERITO_KIM[[#This Row],[Codice Comsy Tecnico Attuale]],COMSY!E:E,0)) -> HUB 98 di DRAGONE GIUSEPPE | O10: =+INDEX(COMSY!G:G,MATCH(INSERITO_KIM[[#This Row],[Codice Comsy Tecnico Attuale]],COMSY!E:E,0)) -> Raffaele | P10: =+INDEX(PIANI!B:B,MATCH(INSERITO_KIM[[#This Row],[Valore]],PIANI!A:A,0)) -> FISSO | Q10: =+INDEX(PIANI!D:D,MATCH(INSERITO_KIM[[#This Row],[Valore]],PIANI!A:A,0)) -> 0
A11: CATERINA MIRI | B11: MRICRN73L67C978R | C11: RES | D11: 24393343 | E11: OR-0030687594 | F11: NR.1217.0601NA.C0178 | G11: 20 | H11: FISSO E MOBILE | I11: 33.9 | J11: Inviato | K11: Attesa provisioning | L11: 45912 | M11: Fastweb Casa light | N11: =+INDEX(COMSY!F:F,MATCH(INSERITO_KIM[[#This Row],[Codice Comsy Tecnico Attuale]],COMSY!E:E,0)) -> HUB 98 di DRAGONE GIUSEPPE | O11: =+INDEX(COMSY!G:G,MATCH(INSERITO_KIM[[#This Row],[Codice Comsy Tecnico Attuale]],COMSY!E:E,0)) -> Raffaele | P11: =+INDEX(PIANI!B:B,MATCH(INSERITO_KIM[[#This Row],[Valore]],PIANI!A:A,0)) -> FISSO | Q11: =+INDEX(PIANI!D:D,MATCH(INSERITO_KIM[[#This Row],[Valore]],PIANI!A:A,0)) -> 0
A12: POTITO FRONTUTO | B12: FRNPTT81L17D643N | C12: RES | D12: 24393232 | E12: OR-0030687255 | F12: NR.1217.0601NA.C0222 | G12: 0 | H12: FISSO | I12: 27.95 | J12: Inviato | K12: In Lavorazione | L12: 45912 | M12: Fastweb Casa light | N12: =+INDEX(COMSY!F:F,MATCH(INSERITO_KIM[[#This Row],[Codice Comsy Tecnico Attuale]],COMSY!E:E,0)) -> REPAIR MOBILE STORE DI CARMINE PALMIERI | O12: =+INDEX(COMSY!G:G,MATCH(INSERITO_KIM[[#This Row],[Codice Comsy Tecnico Attuale]],COMSY!E:E,0)) -> Luigi | P12: =+INDEX(PIANI!B:B,MATCH(INSERITO_KIM[[#This Row],[Valore]],PIANI!A:A,0)) -> FISSO | Q12: =+INDEX(PIANI!D:D,MATCH(INSERITO_KIM[[#This Row],[Valore]],PIANI!A:A,0)) -> 0
A13: GIUSEPPE RICCO | B13: RCCGPP55T16A662J | C13: RES | D13: 23997185 | E13: OR-0030691135 | F13: NR.1217.0601NA.C0221 | G13: 0 | H13: FISSO | I13: 23.95 | J13: Inviato | K13: Attesa provisioning | L13: 45913 | M13: Fastweb Casa light | N13: =+INDEX(COMSY!F:F,MATCH(INSERITO_KIM[[#This Row],[Codice Comsy Tecnico Attuale]],COMSY!E:E,0)) -> RISOLTO LAB MONOPOLI | O13: =+INDEX(COMSY!G:G,MATCH(INSERITO_KIM[[#This Row],[Codice Comsy Tecnico Attuale]],COMSY!E:E,0)) -> Giacomo | P13: =+INDEX(PIANI!B:B,MATCH(INSERITO_KIM[[#This Row],[Valore]],PIANI!A:A,0)) -> FISSO | Q13: =+INDEX(PIANI!D:D,MATCH(INSERITO_KIM[[#This Row],[Valore]],PIANI!A:A,0)) -> 0
... A246: LORENZO PIRAS | B246: PRSLNZ06D22B791G | C246: RES | D246: 24342044 | E246: OR-0030663235 | F246: NR.1217.0601NA.C0221 | G246: 0 | H246: FISSO | I246: 27.95 | J246: Completato | K246: Completato | L246: 45910 | M246: Fastweb NeXXt One Casa FWA | N246: =+INDEX(COMSY!F:F,MATCH(INSERITO_KIM[[#This Row],[Codice Comsy Tecnico Attuale]],COMSY!E:E,0)) -> RISOLTO LAB MONOPOLI | O246: =+INDEX(COMSY!G:G,MATCH(INSERITO_KIM[[#This Row],[Codice Comsy Tecnico Attuale]],COMSY!E:E,0)) -> Giacomo | P246: =+INDEX(PIANI!B:B,MATCH(INSERITO_KIM[[#This Row],[Valore]],PIANI!A:A,0)) -> FISSO | Q246: =+INDEX(PIANI!D:D,MATCH(INSERITO_KIM[[#This Row],[Valore]],PIANI!A:A,0)) -> 0
